Workbook

Sheet Instrucciones
A1: CÓMO USAR ESTE ARCHIVO
A2: Este archivo NO tiene precios cerrados por cantidad. Tiene el framework para calcular cualquier cantidad.
A3: Cada producto dice de qué material se hace. Las medidas del catálogo son REFERENCIAS: se cotiza CUALQUIER medida que pida el cliente.
A4: La primera parte explica cómo COTIZAR (leer). La segunda, cómo CARGAR cosas nuevas (escribir).
A6: ═══ PARTE 1: CÓMO COTIZAR ═══
A7: MODO "pliego" (stickers y etiquetas en papel autoadhesivo u OPP)
A9: 1. Rinde: cuántas piezas entran en una unidad de cobro. Se calcula con la geometría del
A12: MATERIAL (hoja Materiales: 'Área útil ancho/alto (cm)' y 'Separación (cm)'):
A13: columnas × filas que entran = floor((útil + sep) ÷ (pieza + sep)) en cada eje,
A14: probando las DOS orientaciones y tomando la que rinde más. Vale CUALQUIER medida.
A15: Ejemplo: pieza de 12x8 troquelada (área útil 28x44, separación 0,3).
A16: Acostada: 28,3÷12,3 = 2 columnas × 44,3÷8,3 = 5 filas = 10. Parada: 3 × 3 = 9. → 10.
... A150: Los cambios NO llegan al bot hasta que se ingesta desde ahí.

Sheet Colecciones
A1: Colección | B1: Descripción | C1: Material base | D1: Sin mínimo por trabajo
A2: Stickers con forma | B2: Stickers y etiquetas cortados con forma, para uso en interior. Se imprimen en papel autoadhesivo brillo o en OPP (más resistente al roce y a la humedad, y disponible en holográfico, plata, cristal y mate). Se entregan troquelados sueltos o en plancha con medio corte, al mismo precio. Se cotizan por pliego A3. | C2: Papel autoadhesivo troquelado o medio corte
A3: Stickers para exterior | B3: Stickers y etiquetas cortados con forma, impresos en vinilo con tinta UV, que aguanta sol, lluvia y lavado. Para autos, cascos, heladeras, obradores y todo lo que quede a la intemperie. Se cotizan por metro cuadrado. | C3: Vinilo UV troquelado
A4: Carteles y vidrieras | B4: Impresión de gran formato para pared, vidrio o chapa. Adhesivos, que se pegan directo sobre la superficie, o rígidos, montados sobre plástico corrugado para que se sostengan solos. Para vidrieras hay además opciones de microperforado y esmerilado. Se cotizan por metro cuadrado. | C4: Vinilo y lona UV
A5: Banners y lonas | B5: Lona impresa full color con dobladillo y ojalillos, lista para colgar. Para el frente del local, eventos, ferias y publicidad en vía pública. Se cotizan por metro cuadrado. | C5: Lona
A6: Tarjetas personales | B6: Tarjetas de presentación 9x5 cm, full color. Simple o doble faz, en papel ilustración o kraft 280 g, con opción encapsulada (plastificada de ambos lados). Se cotizan por cantidad cerrada: 100, 500 o 1000. | C6: Tarjetas 9x5 simple faz x100
A7: Papelería comercial | B7: Papelería impresa con la marca del negocio: hojas membretadas, sobres, talonarios de factura o remito, notas de pedido, recetarios y carpetas institucionales.
A8: Impresión digital | B8: Impresión de archivos por hoja, en color o blanco y negro, A4 y A3. En papel obra, ilustración u opalina. El precio por hoja baja según la cantidad. | D8: sí
A9: Encuadernación y terminaciones | B9: Trabajos que se hacen sobre un impreso ya listo: anillado, wire-o, fresado, abrochado, laminado, plastificado, troquelado, ojalillos y numerado. Se cobran por unidad y no incluyen la impresión. | D9: sí
A10: Folletería y editorial | B10: Volantes, anotadores, apuntes y libros de estudio.
A11: Gran formato y cartelería | B11: Impresión de gran formato lista para usar: posters, porta banners tipo X y roll-up, y planos. También hay combos que traen la lona impresa junto con su estructura, a precio cerrado.
A12: Señalética y punto de venta | B12: Carteles de seguridad e higiene, cartas y menús plastificados, y carteles de precios para el local.
A13: Eventos y sociales | B13: Tarjetería para eventos: agradecimiento, invitaciones y afines.
A14: Diseño y servicios | B14: Servicios sobre archivos, sin impresión: escaneo y digitalización de planos y documentos en gran formato.
A15: Merchandising | B15: Imanes personalizados para heladera y promoción. Los chicos se cobran por unidad y bajan de precio por cantidad; los troquelados a medida se cotizan por metro cuadrado, mínimo medio m2. | C15: Iman impresión laminada y corte

Sheet Productos
A1: Colección | B1: Producto | C1: Descripción | D1: Material | E1: Ancho (cm) | F1: Alto (cm) | G1: Sinónimos | H1: Formato
A2: Stickers con forma | B2: Stickers 3x3 cm | C2: Los más chicos. Papel autoadhesivo brillo. Troquelados sueltos o en plancha con medio corte, mismo precio. | D2: Papel autoadhesivo troquelado o medio corte | E2: 3 | F2: 3
A3: Stickers con forma | B3: Etiquetas para frascos 6x3 cm | C3: Formato alargado para frascos y botellas chicas. Papel autoadhesivo brillo. | D3: Papel autoadhesivo troquelado o medio corte | E3: 6 | F3: 3
A4: Stickers con forma | B4: Stickers 5x5 cm | C4: Impresión full color, corte con forma. Papel autoadhesivo brillo. Troquelados sueltos o en plancha con medio corte. | D4: Papel autoadhesivo troquelado o medio corte | E4: 5 | F4: 5
A5: Stickers con forma | B5: Stickers en OPP brillo 5x5 cm | C5: OPP brillo: más resistente al roce y a la humedad que el papel. | D5: OPP brillo troquelado | E5: 5 | F5: 5
A6: Stickers con forma | B6: Stickers holográficos 5x5 cm | C6: OPP tornasolado. También en plata, cristal y mate, al mismo precio. | D6: OPP plata, holográfico, cristal o mate troquelado | E6: 5 | F6: 5
A7: Stickers con forma | B7: Etiquetas 9x5 cm | C7: Tamaño tarjeta. Papel autoadhesivo brillo, full color. | D7: Papel autoadhesivo troquelado o medio corte | E7: 9 | F7: 5
A8: Stickers con forma | B8: Etiquetas en OPP brillo 9x5 cm | C8: Tamaño tarjeta en OPP brillo. | D8: OPP brillo troquelado | E8: 9 | F8: 5
A9: Stickers con forma | B9: Stickers 7x7 cm | C9: Impresión full color, corte con forma. Papel autoadhesivo brillo. | D9: Papel autoadhesivo troquelado o medio corte | E9: 7 | F9: 7
A10: Stickers con forma | B10: Stickers en OPP brillo 7x7 cm | C10: OPP brillo: más resistente al roce y a la humedad que el papel. | D10: OPP brillo troquelado | E10: 7 | F10: 7
A11: Stickers con forma | B11: Stickers holográficos 7x7 cm | C11: OPP tornasolado. También en plata, cristal y mate, al mismo precio. | D11: OPP plata, holográfico, cristal o mate troquelado | E11: 7 | F11: 7
A12: Stickers con forma | B12: Stickers 10x10 cm | C12: Impresión full color, corte con forma. Papel autoadhesivo brillo. | D12: Papel autoadhesivo troquelado o medio corte | E12: 10 | F12: 10
A13: Stickers con forma | B13: Stickers en OPP brillo 10x10 cm | C13: OPP brillo: más resistente al roce y a la humedad que el papel. | D13: OPP brillo troquelado | E13: 10 | F13: 10
... A32: Banners y lonas | B32: Banner de lona 4x1 m | C32: Lona impresa full color con dobladillo y ojalillos. | D32: Lona | E32: 400 | F32: 100
A33: Stickers con forma | B33: Stickers en plancha sin cortar | C33: La plancha impresa sin corte: el cliente recorta a mano. Papel autoadhesivo brillo. Sale más barato que el troquelado. | D33: Papel autoadhesivo solo impresión | E33: 5 | F33: 5 | G33: sin cortar, sin troquelar, plancha entera, solo impresión, recorto yo
A34: Stickers con forma | B34: Stickers en OPP brillo sin cortar | C34: Plancha de OPP brillo impresa sin corte. Más resistente al roce y a la humedad que el papel. | D34: OPP brillo | E34: 5 | F34: 5
A35: Stickers con forma | B35: Stickers holográficos sin cortar | C35: Plancha de OPP tornasolado impresa sin corte. También en plata, cristal y mate. | D35: OPP plata, holográfico, cristal o mate | E35: 5 | F35: 5
A36: Carteles y vidrieras | B36: Cartel adhesivo con blanco o barniz | C36: Vinilo UV con una capa de blanco o barniz: da más cuerpo al color sobre superficies oscuras o transparentes. | D36: Vinilo y lona UV con blanco o barniz | E36: 50 | F36: 70 | G36: con blanco, con barniz, para vidrio, para superficie oscura
A37: Tarjetas personales | B37: 100 tarjetas 9x5 cm simple faz | C37: Tarjetas de presentación full color, impresas de un lado. El precio es por las 100. | D37: Tarjetas 9x5 simple faz x100 | E37: 9 | F37: 5 | G37: tarjetas personales, tarjetas de presentación, tarjetas comerciales
A38: Tarjetas personales | B38: 100 tarjetas 9x5 cm simple faz encapsuladas | C38: Impresas de un lado y plastificadas de los dos: más resistentes y con mejor tacto. | D38: Tarjetas 9x5 simple faz encapsuladas x100 | E38: 9 | F38: 5
A39: Tarjetas personales | B39: 100 tarjetas 9x5 cm doble faz | C39: Full color de los dos lados. El precio es por las 100. | D39: Tarjetas 9x5 doble faz x100 | E39: 9 | F39: 5
A40: Tarjetas personales | B40: 100 tarjetas 9x5 cm doble faz encapsuladas | C40: Impresas de los dos lados y plastificadas. | D40: Tarjetas 9x5 doble faz encapsuladas x100 | E40: 9 | F40: 5
A41: Tarjetas personales | B41: 100 tarjetas 9x5 cm en papel kraft simple faz | C41: Papel kraft 280 g, con textura y color natural. Impresas de un lado. | D41: Tarjetas 9x5 kraft simple faz x100 | E41: 9 | F41: 5
A42: Tarjetas personales | B42: 100 tarjetas 9x5 cm en papel kraft doble faz | C42: Papel kraft 280 g, impresas de los dos lados. | D42: Tarjetas 9x5 kraft doble faz x100 | E42: 9 | F42: 5
A43: Tarjetas personales | B43: 500 tarjetas 9x5 cm simple faz | C43: Full color de un lado. El precio es por las 500. | D43: Tarjetas 9x5 simple faz x500 | E43: 9 | F43: 5
A44: Tarjetas personales | B44: 500 tarjetas 9x5 cm simple faz encapsuladas | C44: De un lado y plastificadas. El precio es por las 500. | D44: Tarjetas 9x5 simple faz encapsuladas x500 | E44: 9 | F44: 5
A45: Tarjetas personales | B45: 500 tarjetas 9x5 cm doble faz | C45: Full color de los dos lados. El precio es por las 500. | D45: Tarjetas 9x5 doble faz x500 | E45: 9 | F45: 5
A46: Tarjetas personales | B46: 500 tarjetas 9x5 cm doble faz encapsuladas | C46: De los dos lados y plastificadas. El precio es por las 500. | D46: Tarjetas 9x5 doble faz encapsuladas x500 | E46: 9 | F46: 5
A47: Tarjetas personales | B47: 1000 tarjetas 9x5 cm simple faz | C47: Full color de un lado. El precio es por las 1000. | D47: Tarjetas 9x5 simple faz x1000 | E47: 9 | F47: 5
A48: Tarjetas personales | B48: 1000 tarjetas 9x5 cm simple faz encapsuladas | C48: De un lado y plastificadas. El precio es por las 1000. | D48: Tarjetas 9x5 simple faz encapsuladas x1000 | E48: 9 | F48: 5
A49: Tarjetas personales | B49: 1000 tarjetas 9x5 cm doble faz | C49: Full color de los dos lados. El precio es por las 1000. | D49: Tarjetas 9x5 doble faz x1000 | E49: 9 | F49: 5
A50: Tarjetas personales | B50: 1000 tarjetas 9x5 cm doble faz encapsuladas | C50: De los dos lados y plastificadas. El precio es por las 1000. | D50: Tarjetas 9x5 doble faz encapsuladas x1000 | E50: 9 | F50: 5
A51: Papelería comercial | B51: 500 hojas membretadas A4 | C51: Hojas A4 impresas con el logo y los datos del negocio. El precio es por las 500. | D51: Hojas membretadas A4 x500 | G51: hojas membretadas, papel con logo, membrete | H51: A4
A52: Papelería comercial | B52: 100 sobres impresos | C52: Sobres con el logo y los datos del negocio. El precio es por los 100. | D52: Sobres impresos x100 | E52: 21 | F52: 11 | G52: sobres membretados, sobres con logo
A53: Papelería comercial | B53: 10 talonarios de factura o remito | C53: 10 talonarios A5 de 50 juegos por duplicado, abrochados y troquelados. El precio es por los 10 talonarios. | D53: Talonarios x10 | G53: talonarios, facturas, remitos, notas de pedido, comandas | H53: A5
A54: Papelería comercial | B54: Sobres oficio inglés | C54: Sobre tamaño oficio inglés impreso. Se cobra por unidad y el precio baja por cantidad. | D54: Sobres oficio inglés | E54: 23.5 | F54: 12 | G54: sobres, sobres oficio
A55: Papelería comercial | B55: Carpetas institucionales | C55: Carpeta de presentación A4 cerrada, en cartulina 300 g, troquelada, con solapa y ranura. Sin laminar. Se cobra por unidad. | D55: Carpetas institucionales sin laminar | G55: carpetas, carpetas de presentación, folders | H55: A4 cerrada
A56: Papelería comercial | B56: Carpetas institucionales laminadas | C56: La misma carpeta A4, plastificada: más resistente al uso y al roce. | D56: Carpetas institucionales laminadas | H56: A4 cerrada
A57: Papelería comercial | B57: Recetarios en negro | C57: Talonario de recetas impreso en negro. Mínimo 5 unidades. | D57: Recetarios en negro | G57: recetarios, recetas médicas, blocks de receta | H57: A5 o A6
A58: Papelería comercial | B58: Recetarios en color | C58: Talonario de recetas impreso full color. Mínimo 5 unidades. | D58: Recetarios en color | H58: A5 o A6
...

Sheet Materiales
A1: Material | B1: Unidad | C1: Desde | D1: Hasta | E1: Precio por unidad | F1: Mínimo facturable | G1: Nota | H1: Área útil ancho (cm) | I1: Área útil alto (cm) | J1: Separación (cm) | K1: Sin mínimo por trabajo | L1: Familia | M1: Piezas por paquete | N1: Precio total por tramo
A2: Papel autoadhesivo troquelado o medio corte | B2: pliego A3 | C2: 1 | D2: 1 | E2: 2500 | H2: 28 | I2: 44 | J2: 0.3
A3: Papel autoadhesivo troquelado o medio corte | B3: pliego A3 | C3: 2 | D3: 10 | E3: 2200
A4: Papel autoadhesivo troquelado o medio corte | B4: pliego A3 | C4: 11 | D4: 50 | E4: 2000
A5: Papel autoadhesivo troquelado o medio corte | B5: pliego A3 | C5: 51 | D5: 100 | E5: 1900
A6: Papel autoadhesivo troquelado o medio corte | B6: pliego A3 | C6: 101 | E6: 1710
A7: Papel autoadhesivo solo impresión | B7: pliego A3 | C7: 1 | D7: 100 | E7: 1800 | H7: 31 | I7: 46 | J7: 0
A8: Papel autoadhesivo solo impresión | B8: pliego A3 | C8: 101 | E8: 1620
A9: OPP brillo | B9: pliego A3 | C9: 1 | D9: 9 | E9: 2400 | H9: 31 | I9: 46 | J9: 0
A10: OPP brillo | B10: pliego A3 | C10: 10 | D10: 29 | E10: 2160
A11: OPP brillo | B11: pliego A3 | C11: 30 | E11: 1920
A12: OPP brillo troquelado | B12: pliego A3 | C12: 1 | D12: 9 | E12: 2800 | H12: 28 | I12: 44 | J12: 0.3
A13: OPP brillo troquelado | B13: pliego A3 | C13: 10 | D13: 29 | E13: 2520
A14: OPP brillo troquelado | B14: pliego A3 | C14: 30 | E14: 2240
A15: OPP plata, holográfico, cristal o mate | B15: pliego A3 | C15: 1 | D15: 9 | E15: 2600 | H15: 31 | I15: 46 | J15: 0
A16: OPP plata, holográfico, cristal o mate | B16: pliego A3 | C16: 10 | D16: 29 | E16: 2340
A17: OPP plata, holográfico, cristal o mate | B17: pliego A3 | C17: 30 | E17: 2080
A18: OPP plata, holográfico, cristal o mate troquelado | B18: pliego A3 | C18: 1 | D18: 9 | E18: 3000 | H18: 28 | I18: 44 | J18: 0.3
A19: OPP plata, holográfico, cristal o mate troquelado | B19: pliego A3 | C19: 10 | D19: 29 | E19: 2700
A20: OPP plata, holográfico, cristal o mate troquelado | B20: pliego A3 | C20: 30 | E20: 2400
A21: Lona | B21: m2 | C21: 1 | E21: 16000 | F21: 0.5
A22: Vinilo y lona UV | B22: m2 | C22: 1 | E22: 22000 | F22: 0.5
A23: Vinilo y lona UV con blanco o barniz | B23: m2 | C23: 1 | E23: 26000 | F23: 0.5
A24: Vinilo UV montado en corrugado | B24: m2 | C24: 1 | E24: 30000 | F24: 0.5
A25: Vinilo UV troquelado | B25: m2 | C25: 1 | E25: 28000 | F25: 0.5
A26: Tarjetas 9x5 simple faz x100 | B26: paquete de 100 tarjetas | C26: 1 | E26: 13200 | L26: Tarjetas 9x5 simple faz
A27: Tarjetas 9x5 simple faz encapsuladas x100 | B27: paquete de 100 tarjetas | C27: 1 | E27: 16500 | L27: Tarjetas 9x5 simple faz encapsuladas
A28: Tarjetas 9x5 doble faz x100 | B28: paquete de 100 tarjetas | C28: 1 | E28: 16500 | L28: Tarjetas 9x5 doble faz
A29: Tarjetas 9x5 doble faz encapsuladas x100 | B29: paquete de 100 tarjetas | C29: 1 | E29: 18700 | L29: Tarjetas 9x5 doble faz encapsuladas
A30: Tarjetas 9x5 kraft simple faz x100 | B30: paquete de 100 tarjetas | C30: 1 | E30: 17600 | L30: Tarjetas 9x5 kraft simple faz
A31: Tarjetas 9x5 kraft doble faz x100 | B31: paquete de 100 tarjetas | C31: 1 | E31: 24200 | L31: Tarjetas 9x5 kraft doble faz
A32: Tarjetas 9x5 simple faz x500 | B32: paquete de 500 tarjetas | C32: 1 | E32: 28000 | L32: Tarjetas 9x5 simple faz
A33: Tarjetas 9x5 simple faz encapsuladas x500 | B33: paquete de 500 tarjetas | C33: 1 | E33: 38000 | L33: Tarjetas 9x5 simple faz encapsuladas
A34: Tarjetas 9x5 doble faz x500 | B34: paquete de 500 tarjetas | C34: 1 | E34: 38000 | L34: Tarjetas 9x5 doble faz
A35: Tarjetas 9x5 doble faz encapsuladas x500 | B35: paquete de 500 tarjetas | C35: 1 | E35: 45000 | L35: Tarjetas 9x5 doble faz encapsuladas
A36: Tarjetas 9x5 simple faz x1000 | B36: paquete de 1000 tarjetas | C36: 1 | E36: 42000 | L36: Tarjetas 9x5 simple faz
A37: Tarjetas 9x5 simple faz encapsuladas x1000 | B37: paquete de 1000 tarjetas | C37: 1 | E37: 54000 | L37: Tarjetas 9x5 simple faz encapsuladas
... A39: Tarjetas 9x5 doble faz encapsuladas x1000 | B39: paquete de 1000 tarjetas | C39: 1 | E39: 59000 | L39: Tarjetas 9x5 doble faz encapsuladas
A40: Hojas membretadas A4 x500 | B40: paquete de 500 hojas | C40: 1 | E40: 35000
A41: Sobres impresos x100 | B41: paquete de 100 sobres | C41: 1 | E41: 25000
...

Sheet Pendientes
A1: Producto | B1: Descripción | C1: Cómo se cobra | D1: Notas

Sheet Parámetros
A1: Parámetro | B1: Valor | C1: Nota
A2: Mínimo por trabajo | B2: 4000 | C2: Ningún trabajo se cobra menos que esto.
A3: Redondeo | B3: 100 | C3: El total final se redondea al múltiplo de $100 más cercano.
A4: Moneda | B4: ARS | C4: Pesos argentinos, IVA incluido.

Sheet Casos de prueba
A1: Pedido | B1: Cantidad | C1: Material | D1: Ancho (cm) | E1: Alto (cm) | F1: Piezas por unidad de cobro | G1: Precio correcto
A2: 250 stickers 3x3 cm | B2: 250 | C2: Papel autoadhesivo troquelado o medio corte | D2: 3 | E2: 3 | F2: 104 | G2: 6600
A3: 250 etiquetas para frascos 6x3 cm | B3: 250 | C3: Papel autoadhesivo troquelado o medio corte | D3: 6 | E3: 3 | F3: 56 | G3: 11000
A4: 100 stickers 5x5 cm | B4: 100 | C4: Papel autoadhesivo troquelado o medio corte | D4: 5 | E4: 5 | F4: 40 | G4: 6600
A5: 100 stickers redondos de 5 cm | B5: 100 | C5: Papel autoadhesivo troquelado o medio corte | D5: 5 | E5: 5 | F5: 40 | G5: 6600
A6: 100 stickers en OPP brillo 5x5 cm | B6: 100 | C6: OPP brillo troquelado | D6: 5 | E6: 5 | F6: 40 | G6: 8400
A7: 100 stickers holográficos 5x5 cm | B7: 100 | C7: OPP plata, holográfico, cristal o mate troquelado | D7: 5 | E7: 5 | F7: 40 | G7: 9000
A8: 250 stickers 5x5 cm | B8: 250 | C8: Papel autoadhesivo troquelado o medio corte | D8: 5 | E8: 5 | F8: 40 | G8: 15400
A9: 250 stickers redondos de 5 cm | B9: 250 | C9: Papel autoadhesivo troquelado o medio corte | D9: 5 | E9: 5 | F9: 40 | G9: 15400
A10: 500 stickers 5x5 cm | B10: 500 | C10: Papel autoadhesivo troquelado o medio corte | D10: 5 | E10: 5 | F10: 40 | G10: 26000
A11: 100 etiquetas 9x5 cm | B11: 100 | C11: Papel autoadhesivo troquelado o medio corte | D11: 9 | E11: 5 | F11: 24 | G11: 11000
A12: 100 etiquetas en OPP brillo 9x5 cm | B12: 100 | C12: OPP brillo troquelado | D12: 9 | E12: 5 | F12: 24 | G12: 14000
A13: 100 stickers 7x7 cm | B13: 100 | C13: Papel autoadhesivo troquelado o medio corte | D13: 7 | E13: 7 | F13: 18 | G13: 13200
... A21: 100 etiquetas 14x10 cm | B21: 100 | C21: Papel autoadhesivo troquelado o medio corte | D21: 14 | E21: 10 | F21: 6 | G21: 34000
A22: 100 stickers en vinilo UV 5x5 cm | B22: 100 | C22: Vinilo UV troquelado | D22: 5 | E22: 5 | G22: 14000
A23: 250 stickers en vinilo UV 5x5 cm | B23: 250 | C23: Vinilo UV troquelado | D23: 5 | E23: 5 | G23: 17500
A24: 100 stickers en vinilo UV 7x7 cm | B24: 100 | C24: Vinilo UV troquelado | D24: 7 | E24: 7 | G24: 14000
A25: 100 stickers en vinilo UV 10x10 cm | B25: 100 | C25: Vinilo UV troquelado | D25: 10 | E25: 10 | G25: 28000
A26: 50 etiquetas en vinilo UV 14x10 cm | B26: 50 | C26: Vinilo UV troquelado | D26: 14 | E26: 10 | G26: 19600
A27: 100 etiquetas en vinilo UV 14x10 cm | B27: 100 | C27: Vinilo UV troquelado | D27: 14 | E27: 10 | G27: 39200
A28: Cartel adhesivo 50x70 cm | B28: 1 | C28: Vinilo y lona UV | D28: 50 | E28: 70 | G28: 11000
A29: Cartel rígido 50x70 cm | B29: 1 | C29: Vinilo UV montado en corrugado | D29: 50 | E29: 70 | G29: 15000
A30: Cartel adhesivo 70x100 cm | B30: 1 | C30: Vinilo y lona UV | D30: 70 | E30: 100 | G30: 15400
A31: Cartel rígido 70x100 cm | B31: 1 | C31: Vinilo UV montado en corrugado | D31: 70 | E31: 100 | G31: 21000
A32: Vinilo para vidriera 1x1 m | B32: 1 | C32: Vinilo y lona UV | D32: 100 | E32: 100 | G32: 22000
A33: Cartel rígido 1x1 m | B33: 1 | C33: Vinilo UV montado en corrugado | D33: 100 | E33: 100 | G33: 30000
... A40: Banner de lona 4x1 m | B40: 1 | C40: Lona | D40: 400 | E40: 100 | G40: 64000
A41: 500 stickers 2x2 cm (medida libre) | B41: 500 | C41: Papel autoadhesivo troquelado o medio corte | D41: 2 | E41: 2 | F41: 228 | G41: 6600
A42: 100 etiquetas 5x8 cm (medida libre) | B42: 100 | C42: Papel autoadhesivo troquelado o medio corte | D42: 5 | E42: 8 | F42: 25 | G42: 8800
A43: 80 etiquetas 20x6 cm (gana la orientación rotada) | B43: 80 | C43: Papel autoadhesivo troquelado o medio corte | D43: 20 | E43: 6 | F43: 8 | G43: 22000
A44: 300 etiquetas 4x4 cm solo impresión (sin separación) | B44: 300 | C44: Papel autoadhesivo solo impresión | D44: 4 | E44: 4 | F44: 77 | G44: 7200
A45: 20 stickers 30x45 cm (no entra en el pliego) | B45: 20 | C45: Papel autoadhesivo troquelado o medio corte | D45: 30 | E45: 45 | F45: 0 | G45: Derivar a consulta: no entra en el pliego
A46: 10 stickers 3x3 cm (activa el mínimo por trabajo) | B46: 10 | C46: Papel autoadhesivo troquelado o medio corte | D46: 3 | E46: 3 | F46: 104 | G46: 4000
A47: 1 lona de 90x60 cm (activa el redondeo) | B47: 1 | C47: Lona | D47: 90 | E47: 60 | G47: 8600
A48: 100 tarjetas 9x5 simple faz | B48: 100 | C48: Tarjetas 9x5 simple faz x100 | D48: 9 | E48: 5 | G48: 13200
A49: 500 tarjetas 9x5 doble faz | B49: 500 | C49: Tarjetas 9x5 doble faz x500 | D49: 9 | E49: 5 | G49: 38000
A50: 1000 tarjetas 9x5 simple faz encapsuladas | B50: 1000 | C50: Tarjetas 9x5 simple faz encapsuladas x1000 | D50: 9 | E50: 5 | G50: 54000
A51: 500 hojas membretadas A4 | B51: 500 | C51: Hojas membretadas A4 x500 | D51: 21 | E51: 29.7 | G51: 35000
A52: 10 talonarios de factura | B52: 10 | C52: Talonarios x10 | D52: 15 | E52: 21 | G52: 54000
A53: 500 volantes A6 | B53: 500 | C53: Volantes A6 x500 | D53: 10 | E53: 15 | G53: 12000
...

Sheet _listas
A1: Materiales — desplegable de Productos | B1: Colecciones — desplegable de Productos
A2: {=IFERROR(INDEX(Materiales!$A$2:$A$600,MATCH(0,COUNTIF($A$1:A1,Materiales!$A$2:$A$600)+IF(Materiales!$A$2:$A$600="",1,0),0)),"")} | B2: {=IFERROR(INDEX(Colecciones!$A$2:$A$600,MATCH(0,COUNTIF($B$1:B1,Colecciones!$A$2:$A$600)+IF(Colecciones!$A$2:$A$600="",1,0),0)),"")}
A3: {=IFERROR(INDEX(Materiales!$A$2:$A$600,MATCH(0,COUNTIF($A$1:A2,Materiales!$A$2:$A$600)+IF(Materiales!$A$2:$A$600="",1,0),0)),"")} | B3: {=IFERROR(INDEX(Colecciones!$A$2:$A$600,MATCH(0,COUNTIF($B$1:B2,Colecciones!$A$2:$A$600)+IF(Colecciones!$A$2:$A$600="",1,0),0)),"")}
A4: {=IFERROR(INDEX(Materiales!$A$2:$A$600,MATCH(0,COUNTIF($A$1:A3,Materiales!$A$2:$A$600)+IF(Materiales!$A$2:$A$600="",1,0),0)),"")} | B4: {=IFERROR(INDEX(Colecciones!$A$2:$A$600,MATCH(0,COUNTIF($B$1:B3,Colecciones!$A$2:$A$600)+IF(Colecciones!$A$2:$A$600="",1,0),0)),"")}
A5: {=IFERROR(INDEX(Materiales!$A$2:$A$600,MATCH(0,COUNTIF($A$1:A4,Materiales!$A$2:$A$600)+IF(Materiales!$A$2:$A$600="",1,0),0)),"")} | B5: {=IFERROR(INDEX(Colecciones!$A$2:$A$600,MATCH(0,COUNTIF($B$1:B4,Colecciones!$A$2:$A$600)+IF(Colecciones!$A$2:$A$600="",1,0),0)),"")}
A6: {=IFERROR(INDEX(Materiales!$A$2:$A$600,MATCH(0,COUNTIF($A$1:A5,Materiales!$A$2:$A$600)+IF(Materiales!$A$2:$A$600="",1,0),0)),"")} | B6: {=IFERROR(INDEX(Colecciones!$A$2:$A$600,MATCH(0,COUNTIF($B$1:B5,Colecciones!$A$2:$A$600)+IF(Colecciones!$A$2:$A$600="",1,0),0)),"")}
A7: {=IFERROR(INDEX(Materiales!$A$2:$A$600,MATCH(0,COUNTIF($A$1:A6,Materiales!$A$2:$A$600)+IF(Materiales!$A$2:$A$600="",1,0),0)),"")} | B7: {=IFERROR(INDEX(Colecciones!$A$2:$A$600,MATCH(0,COUNTIF($B$1:B6,Colecciones!$A$2:$A$600)+IF(Colecciones!$A$2:$A$600="",1,0),0)),"")}
A8: {=IFERROR(INDEX(Materiales!$A$2:$A$600,MATCH(0,COUNTIF($A$1:A7,Materiales!$A$2:$A$600)+IF(Materiales!$A$2:$A$600="",1,0),0)),"")} | B8: {=IFERROR(INDEX(Colecciones!$A$2:$A$600,MATCH(0,COUNTIF($B$1:B7,Colecciones!$A$2:$A$600)+IF(Colecciones!$A$2:$A$600="",1,0),0)),"")}
A9: {=IFERROR(INDEX(Materiales!$A$2:$A$600,MATCH(0,COUNTIF($A$1:A8,Materiales!$A$2:$A$600)+IF(Materiales!$A$2:$A$600="",1,0),0)),"")} | B9: {=IFERROR(INDEX(Colecciones!$A$2:$A$600,MATCH(0,COUNTIF($B$1:B8,Colecciones!$A$2:$A$600)+IF(Colecciones!$A$2:$A$600="",1,0),0)),"")}
A10: {=IFERROR(INDEX(Materiales!$A$2:$A$600,MATCH(0,COUNTIF($A$1:A9,Materiales!$A$2:$A$600)+IF(Materiales!$A$2:$A$600="",1,0),0)),"")} | B10: {=IFERROR(INDEX(Colecciones!$A$2:$A$600,MATCH(0,COUNTIF($B$1:B9,Colecciones!$A$2:$A$600)+IF(Colecciones!$A$2:$A$600="",1,0),0)),"")}
A11: {=IFERROR(INDEX(Materiales!$A$2:$A$600,MATCH(0,COUNTIF($A$1:A10,Materiales!$A$2:$A$600)+IF(Materiales!$A$2:$A$600="",1,0),0)),"")} | B11: {=IFERROR(INDEX(Colecciones!$A$2:$A$600,MATCH(0,COUNTIF($B$1:B10,Colecciones!$A$2:$A$600)+IF(Colecciones!$A$2:$A$600="",1,0),0)),"")}
A12: {=IFERROR(INDEX(Materiales!$A$2:$A$600,MATCH(0,COUNTIF($A$1:A11,Materiales!$A$2:$A$600)+IF(Materiales!$A$2:$A$600="",1,0),0)),"")} | B12: {=IFERROR(INDEX(Colecciones!$A$2:$A$600,MATCH(0,COUNTIF($B$1:B11,Colecciones!$A$2:$A$600)+IF(Colecciones!$A$2:$A$600="",1,0),0)),"")}
A13: {=IFERROR(INDEX(Materiales!$A$2:$A$600,MATCH(0,COUNTIF($A$1:A12,Materiales!$A$2:$A$600)+IF(Materiales!$A$2:$A$600="",1,0),0)),"")} | B13: {=IFERROR(INDEX(Colecciones!$A$2:$A$600,MATCH(0,COUNTIF($B$1:B12,Colecciones!$A$2:$A$600)+IF(Colecciones!$A$2:$A$600="",1,0),0)),"")}
... A600: {=IFERROR(INDEX(Materiales!$A$2:$A$600,MATCH(0,COUNTIF($A$1:A599,Materiales!$A$2:$A$600)+IF(Materiales!$A$2:$A$600="",1,0),0)),"")} | B600: {=IFERROR(INDEX(Colecciones!$A$2:$A$600,MATCH(0,COUNTIF($B$1:B599,Colecciones!$A$2:$A$600)+IF(Colecciones!$A$2:$A$600="",1,0),0)),"")}
